<mujoco model="two_link">
  <compiler angle="radian"/>
  <option collision="predefined"/>

  <asset>
    <mesh file="ball-joint.stl"/>
    <mesh file="hand.stl"/>
  </asset>
  <worldbody>
   <body name="base" pos="0 0 0.0">
     <geom name="base" type="box" size="0.1 0.1 0.1" mass="1" rgba="0 1 0 1"/>
     <body name="link1" pos="0 0 0.0">
       <geom name="link1" type="mesh" mesh="ball-joint" mass="1" rgba="1 0 0 1"/>
       <joint name="joint1" type="hinge" axis="1 0 0" limited="true" range="-3.14 3.14"/>
       <body name="link2" pos="0 0 0.6">
         <geom name="link2" type="mesh" mesh="ball-joint" mass="1" rgba="0 0 1 1"/>
         <joint name="joint2" type="hinge" axis="1 0 0" limited="true" range="-3.14 3.14"/> 
         <body name="link3" pos="0 0 0.6">
           <geom name="link3" type="mesh" mesh="hand" mass="1" rgba="1 1 1 1"/>
           <joint name="joint3" type="hinge" axis="1 0 0" limited="true" range="-3.14 3.14"/>
         </body>
       </body>
     </body>
   </body>
 </worldbody>

   <actuator>
     <position name="poscon_joint1" joint="joint1" kp="60" ctrllimited="true" ctrlrange="-100 100"/>
     <velocity name="velcon_joint1" joint="joint1" kv="10"/>
     <position name="joint2" joint="joint2" kp="30" ctrllimited="true" ctrlrange="-100 100"/>
     <velocity name="velcon_joint2" joint="joint2" kv="20"/>
     <position name="joint3" joint="joint3" kp="15" ctrllimited="true" ctrlrange="-100 100"/>
     <velocity name="velcon_joint3" joint="joint3" kv="10"/>
   </actuator>
</mujoco>
