<mujoco model="throw_arm">
  <compiler angle="radian"/>
  <option collision="predefined"/>

  <!-- <asset> -->

  <worldbody>
    <body name="base" pos="0 0 0.0">
      <geom name="base" type="box" size="0.1 0.1 0.1" mass="1" rgba="0 1 0 1"/>
      <body name="link1" pos="0 0 0.0">
        <geom name="link1" type="mesh" mesh="ball-joint" mass="1" rgba="1 0 0 1"/>
        <joint name="joint1" type="hinge" axis="1 0 0" limited="true" range="-3.14 3.14"/>
        <body name="link2" pos="0 0 0.6">
          <geom name="link2" type="mesh" mesh="ball-joint" mass="1" rgba="0 0 1 1"/>
          <joint name="joint2" type="hinge" axis="1 0 0" limited="true" range="-3.14 3.14"/>
	</body>
      </body>
    </body>
  </worldbody>

  <actuator>
    <position name="pos_joint1" joint="joint1" kp="1" ctrllimited="true">
    

  
